Workbook

Sheet Start Here
B2: Simple Money Playbook
B4: Compound Interest Calculator
B6: Make this yours first
B7: This copy is view-only. Go to File -> Make a copy to save your own editable version, then change the blue cells to your own numbers.
B9: What it shows
B10: Put in a starting amount, a monthly contribution, a return rate, and a number of years. It shows what that could grow to, how much of it is money you added vs. growth on top, and the price of waiting five years to start.
B12: How to use it
B13: 1. Make your own copy (File -> Make a copy).
B14: 2. On the 'Calculator' tab, change the four blue cells. Everything else, including the chart, updates itself.
B16: The one idea
B17: Time is the ingredient you cannot buy back. The chart makes it obvious: the earlier you start, the more the growth does the heavy lifting instead of you.
B19: About the numbers
... B22: More free lessons + recipes: simplemoneyplaybook.com

Sheet Calculator
B1: Compound Interest Calculator
B2: See what steady saving can become when growth compounds on top of growth, and what it costs to wait.
B4: What you'll put in | E4: What it becomes
B5: Starting amount | C5: 1000 | E5: Future value | F5: =FV(C7/100/12,C8*12,-C6,-C5)
B6: Monthly contribution | C6: 250 | E6: Total you put in | F6: =C5+C6*12*C8
B7: Annual return % | C7: 7 | E7: Growth on top | F7: =F5-F6
B8: Years to grow | C8: 30
B10: =IF(C8<=0,"Enter your numbers above to see the projection.","In "&C8&" years, putting in $"&TEXT(C6,"#,##0")&"/mo at "&C7&"% could grow to $"&TEXT(F5,"#,##0")&". Of that, $"&TEXT(F7,"#,##0")&" is growth you did not put in.")
B12: =IF(C8>5,"Wait 5 years to start and you would reach only $"&TEXT(FV(C7/100/12,(C8-5)*12,-C6,-C5),"#,##0")&". That 5-year delay costs about $"&TEXT(F5-FV(C7/100/12,(C8-5)*12,-C6,-C5),"#,##0")&".","Starting early is the whole game. Even a few years makes a real difference.")
B15: The chart to the right stacks what you put in (navy) and the growth on top (gold). Watch the gold overtake the navy the longer you stay in.
B17: Illustration only, not financial advice. Returns are not guaranteed. simplemoneyplaybook.com

Sheet Growth Data
B1: Growth Data (the numbers behind the chart)
B3: Year | C3: Contributed | D3: Growth | E3: Balance
B4: =IF(0<=Calculator!$C$8,0,NA()) | C4: =IF(ISNA(B4),NA(),Calculator!$C$5+Calculator!$C$6*12*B4) | D4: =IF(ISNA(B4),NA(),E4-C4) | E4: =IF(ISNA(B4),NA(),FV(Calculator!$C$7/100/12,B4*12,-Calculator!$C$6,-Calculator!$C$5))
B5: =IF(1<=Calculator!$C$8,1,NA()) | C5: =IF(ISNA(B5),NA(),Calculator!$C$5+Calculator!$C$6*12*B5) | D5: =IF(ISNA(B5),NA(),E5-C5) | E5: =IF(ISNA(B5),NA(),FV(Calculator!$C$7/100/12,B5*12,-Calculator!$C$6,-Calculator!$C$5))
B6: =IF(2<=Calculator!$C$8,2,NA()) | C6: =IF(ISNA(B6),NA(),Calculator!$C$5+Calculator!$C$6*12*B6) | D6: =IF(ISNA(B6),NA(),E6-C6) | E6: =IF(ISNA(B6),NA(),FV(Calculator!$C$7/100/12,B6*12,-Calculator!$C$6,-Calculator!$C$5))
B7: =IF(3<=Calculator!$C$8,3,NA()) | C7: =IF(ISNA(B7),NA(),Calculator!$C$5+Calculator!$C$6*12*B7) | D7: =IF(ISNA(B7),NA(),E7-C7) | E7: =IF(ISNA(B7),NA(),FV(Calculator!$C$7/100/12,B7*12,-Calculator!$C$6,-Calculator!$C$5))
B8: =IF(4<=Calculator!$C$8,4,NA()) | C8: =IF(ISNA(B8),NA(),Calculator!$C$5+Calculator!$C$6*12*B8) | D8: =IF(ISNA(B8),NA(),E8-C8) | E8: =IF(ISNA(B8),NA(),FV(Calculator!$C$7/100/12,B8*12,-Calculator!$C$6,-Calculator!$C$5))
B9: =IF(5<=Calculator!$C$8,5,NA()) | C9: =IF(ISNA(B9),NA(),Calculator!$C$5+Calculator!$C$6*12*B9) | D9: =IF(ISNA(B9),NA(),E9-C9) | E9: =IF(ISNA(B9),NA(),FV(Calculator!$C$7/100/12,B9*12,-Calculator!$C$6,-Calculator!$C$5))
B10: =IF(6<=Calculator!$C$8,6,NA()) | C10: =IF(ISNA(B10),NA(),Calculator!$C$5+Calculator!$C$6*12*B10) | D10: =IF(ISNA(B10),NA(),E10-C10) | E10: =IF(ISNA(B10),NA(),FV(Calculator!$C$7/100/12,B10*12,-Calculator!$C$6,-Calculator!$C$5))
B11: =IF(7<=Calculator!$C$8,7,NA()) | C11: =IF(ISNA(B11),NA(),Calculator!$C$5+Calculator!$C$6*12*B11) | D11: =IF(ISNA(B11),NA(),E11-C11) | E11: =IF(ISNA(B11),NA(),FV(Calculator!$C$7/100/12,B11*12,-Calculator!$C$6,-Calculator!$C$5))
B12: =IF(8<=Calculator!$C$8,8,NA()) | C12: =IF(ISNA(B12),NA(),Calculator!$C$5+Calculator!$C$6*12*B12) | D12: =IF(ISNA(B12),NA(),E12-C12) | E12: =IF(ISNA(B12),NA(),FV(Calculator!$C$7/100/12,B12*12,-Calculator!$C$6,-Calculator!$C$5))
B13: =IF(9<=Calculator!$C$8,9,NA()) | C13: =IF(ISNA(B13),NA(),Calculator!$C$5+Calculator!$C$6*12*B13) | D13: =IF(ISNA(B13),NA(),E13-C13) | E13: =IF(ISNA(B13),NA(),FV(Calculator!$C$7/100/12,B13*12,-Calculator!$C$6,-Calculator!$C$5))
B14: =IF(10<=Calculator!$C$8,10,NA()) | C14: =IF(ISNA(B14),NA(),Calculator!$C$5+Calculator!$C$6*12*B14) | D14: =IF(ISNA(B14),NA(),E14-C14) | E14: =IF(ISNA(B14),NA(),FV(Calculator!$C$7/100/12,B14*12,-Calculator!$C$6,-Calculator!$C$5))
B15: =IF(11<=Calculator!$C$8,11,NA()) | C15: =IF(ISNA(B15),NA(),Calculator!$C$5+Calculator!$C$6*12*B15) | D15: =IF(ISNA(B15),NA(),E15-C15) | E15: =IF(ISNA(B15),NA(),FV(Calculator!$C$7/100/12,B15*12,-Calculator!$C$6,-Calculator!$C$5))
B16: =IF(12<=Calculator!$C$8,12,NA()) | C16: =IF(ISNA(B16),NA(),Calculator!$C$5+Calculator!$C$6*12*B16) | D16: =IF(ISNA(B16),NA(),E16-C16) | E16: =IF(ISNA(B16),NA(),FV(Calculator!$C$7/100/12,B16*12,-Calculator!$C$6,-Calculator!$C$5))
B17: =IF(13<=Calculator!$C$8,13,NA()) | C17: =IF(ISNA(B17),NA(),Calculator!$C$5+Calculator!$C$6*12*B17) | D17: =IF(ISNA(B17),NA(),E17-C17) | E17: =IF(ISNA(B17),NA(),FV(Calculator!$C$7/100/12,B17*12,-Calculator!$C$6,-Calculator!$C$5))
B18: =IF(14<=Calculator!$C$8,14,NA()) | C18: =IF(ISNA(B18),NA(),Calculator!$C$5+Calculator!$C$6*12*B18) | D18: =IF(ISNA(B18),NA(),E18-C18) | E18: =IF(ISNA(B18),NA(),FV(Calculator!$C$7/100/12,B18*12,-Calculator!$C$6,-Calculator!$C$5))
B19: =IF(15<=Calculator!$C$8,15,NA()) | C19: =IF(ISNA(B19),NA(),Calculator!$C$5+Calculator!$C$6*12*B19) | D19: =IF(ISNA(B19),NA(),E19-C19) | E19: =IF(ISNA(B19),NA(),FV(Calculator!$C$7/100/12,B19*12,-Calculator!$C$6,-Calculator!$C$5))
B20: =IF(16<=Calculator!$C$8,16,NA()) | C20: =IF(ISNA(B20),NA(),Calculator!$C$5+Calculator!$C$6*12*B20) | D20: =IF(ISNA(B20),NA(),E20-C20) | E20: =IF(ISNA(B20),NA(),FV(Calculator!$C$7/100/12,B20*12,-Calculator!$C$6,-Calculator!$C$5))
B21: =IF(17<=Calculator!$C$8,17,NA()) | C21: =IF(ISNA(B21),NA(),Calculator!$C$5+Calculator!$C$6*12*B21) | D21: =IF(ISNA(B21),NA(),E21-C21) | E21: =IF(ISNA(B21),NA(),FV(Calculator!$C$7/100/12,B21*12,-Calculator!$C$6,-Calculator!$C$5))
B22: =IF(18<=Calculator!$C$8,18,NA()) | C22: =IF(ISNA(B22),NA(),Calculator!$C$5+Calculator!$C$6*12*B22) | D22: =IF(ISNA(B22),NA(),E22-C22) | E22: =IF(ISNA(B22),NA(),FV(Calculator!$C$7/100/12,B22*12,-Calculator!$C$6,-Calculator!$C$5))
B23: =IF(19<=Calculator!$C$8,19,NA()) | C23: =IF(ISNA(B23),NA(),Calculator!$C$5+Calculator!$C$6*12*B23) | D23: =IF(ISNA(B23),NA(),E23-C23) | E23: =IF(ISNA(B23),NA(),FV(Calculator!$C$7/100/12,B23*12,-Calculator!$C$6,-Calculator!$C$5))
B24: =IF(20<=Calculator!$C$8,20,NA()) | C24: =IF(ISNA(B24),NA(),Calculator!$C$5+Calculator!$C$6*12*B24) | D24: =IF(ISNA(B24),NA(),E24-C24) | E24: =IF(ISNA(B24),NA(),FV(Calculator!$C$7/100/12,B24*12,-Calculator!$C$6,-Calculator!$C$5))
B25: =IF(21<=Calculator!$C$8,21,NA()) | C25: =IF(ISNA(B25),NA(),Calculator!$C$5+Calculator!$C$6*12*B25) | D25: =IF(ISNA(B25),NA(),E25-C25) | E25: =IF(ISNA(B25),NA(),FV(Calculator!$C$7/100/12,B25*12,-Calculator!$C$6,-Calculator!$C$5))
B26: =IF(22<=Calculator!$C$8,22,NA()) | C26: =IF(ISNA(B26),NA(),Calculator!$C$5+Calculator!$C$6*12*B26) | D26: =IF(ISNA(B26),NA(),E26-C26) | E26: =IF(ISNA(B26),NA(),FV(Calculator!$C$7/100/12,B26*12,-Calculator!$C$6,-Calculator!$C$5))
B27: =IF(23<=Calculator!$C$8,23,NA()) | C27: =IF(ISNA(B27),NA(),Calculator!$C$5+Calculator!$C$6*12*B27) | D27: =IF(ISNA(B27),NA(),E27-C27) | E27: =IF(ISNA(B27),NA(),FV(Calculator!$C$7/100/12,B27*12,-Calculator!$C$6,-Calculator!$C$5))
B28: =IF(24<=Calculator!$C$8,24,NA()) | C28: =IF(ISNA(B28),NA(),Calculator!$C$5+Calculator!$C$6*12*B28) | D28: =IF(ISNA(B28),NA(),E28-C28) | E28: =IF(ISNA(B28),NA(),FV(Calculator!$C$7/100/12,B28*12,-Calculator!$C$6,-Calculator!$C$5))
B29: =IF(25<=Calculator!$C$8,25,NA()) | C29: =IF(ISNA(B29),NA(),Calculator!$C$5+Calculator!$C$6*12*B29) | D29: =IF(ISNA(B29),NA(),E29-C29) | E29: =IF(ISNA(B29),NA(),FV(Calculator!$C$7/100/12,B29*12,-Calculator!$C$6,-Calculator!$C$5))
B30: =IF(26<=Calculator!$C$8,26,NA()) | C30: =IF(ISNA(B30),NA(),Calculator!$C$5+Calculator!$C$6*12*B30) | D30: =IF(ISNA(B30),NA(),E30-C30) | E30: =IF(ISNA(B30),NA(),FV(Calculator!$C$7/100/12,B30*12,-Calculator!$C$6,-Calculator!$C$5))
B31: =IF(27<=Calculator!$C$8,27,NA()) | C31: =IF(ISNA(B31),NA(),Calculator!$C$5+Calculator!$C$6*12*B31) | D31: =IF(ISNA(B31),NA(),E31-C31) | E31: =IF(ISNA(B31),NA(),FV(Calculator!$C$7/100/12,B31*12,-Calculator!$C$6,-Calculator!$C$5))
B32: =IF(28<=Calculator!$C$8,28,NA()) | C32: =IF(ISNA(B32),NA(),Calculator!$C$5+Calculator!$C$6*12*B32) | D32: =IF(ISNA(B32),NA(),E32-C32) | E32: =IF(ISNA(B32),NA(),FV(Calculator!$C$7/100/12,B32*12,-Calculator!$C$6,-Calculator!$C$5))
B33: =IF(29<=Calculator!$C$8,29,NA()) | C33: =IF(ISNA(B33),NA(),Calculator!$C$5+Calculator!$C$6*12*B33) | D33: =IF(ISNA(B33),NA(),E33-C33) | E33: =IF(ISNA(B33),NA(),FV(Calculator!$C$7/100/12,B33*12,-Calculator!$C$6,-Calculator!$C$5))
B34: =IF(30<=Calculator!$C$8,30,NA()) | C34: =IF(ISNA(B34),NA(),Calculator!$C$5+Calculator!$C$6*12*B34) | D34: =IF(ISNA(B34),NA(),E34-C34) | E34: =IF(ISNA(B34),NA(),FV(Calculator!$C$7/100/12,B34*12,-Calculator!$C$6,-Calculator!$C$5))
B35: =IF(31<=Calculator!$C$8,31,NA()) | C35: =IF(ISNA(B35),NA(),Calculator!$C$5+Calculator!$C$6*12*B35) | D35: =IF(ISNA(B35),NA(),E35-C35) | E35: =IF(ISNA(B35),NA(),FV(Calculator!$C$7/100/12,B35*12,-Calculator!$C$6,-Calculator!$C$5))
B36: =IF(32<=Calculator!$C$8,32,NA()) | C36: =IF(ISNA(B36),NA(),Calculator!$C$5+Calculator!$C$6*12*B36) | D36: =IF(ISNA(B36),NA(),E36-C36) | E36: =IF(ISNA(B36),NA(),FV(Calculator!$C$7/100/12,B36*12,-Calculator!$C$6,-Calculator!$C$5))
B37: =IF(33<=Calculator!$C$8,33,NA()) | C37: =IF(ISNA(B37),NA(),Calculator!$C$5+Calculator!$C$6*12*B37) | D37: =IF(ISNA(B37),NA(),E37-C37) | E37: =IF(ISNA(B37),NA(),FV(Calculator!$C$7/100/12,B37*12,-Calculator!$C$6,-Calculator!$C$5))
B38: =IF(34<=Calculator!$C$8,34,NA()) | C38: =IF(ISNA(B38),NA(),Calculator!$C$5+Calculator!$C$6*12*B38) | D38: =IF(ISNA(B38),NA(),E38-C38) | E38: =IF(ISNA(B38),NA(),FV(Calculator!$C$7/100/12,B38*12,-Calculator!$C$6,-Calculator!$C$5))
B39: =IF(35<=Calculator!$C$8,35,NA()) | C39: =IF(ISNA(B39),NA(),Calculator!$C$5+Calculator!$C$6*12*B39) | D39: =IF(ISNA(B39),NA(),E39-C39) | E39: =IF(ISNA(B39),NA(),FV(Calculator!$C$7/100/12,B39*12,-Calculator!$C$6,-Calculator!$C$5))
B40: =IF(36<=Calculator!$C$8,36,NA()) | C40: =IF(ISNA(B40),NA(),Calculator!$C$5+Calculator!$C$6*12*B40) | D40: =IF(ISNA(B40),NA(),E40-C40) | E40: =IF(ISNA(B40),NA(),FV(Calculator!$C$7/100/12,B40*12,-Calculator!$C$6,-Calculator!$C$5))
B41: =IF(37<=Calculator!$C$8,37,NA()) | C41: =IF(ISNA(B41),NA(),Calculator!$C$5+Calculator!$C$6*12*B41) | D41: =IF(ISNA(B41),NA(),E41-C41) | E41: =IF(ISNA(B41),NA(),FV(Calculator!$C$7/100/12,B41*12,-Calculator!$C$6,-Calculator!$C$5))
...
